Workbook
Name Emergency_Cost_ex: 'Maintenance Cost Analysis Pivot'!$H$61
Name Emergency_Percent: 'Maintenance Cost Analysis Pivot'!$K$61
Name NativeTimeline_Reported: #N/A
Name Plant_Comp: 'Maintenance Cost Dashboard'!#REF!
Name Plant_ex: #REF!
Name Plant_Ext: 'Maintenance Cost Analysis Pivot'!$G$61
Name Plant_new: 'Maintenance Cost Dashboard'!#REF!
Name Preventive_Cost_ex: 'Maintenance Cost Analysis Pivot'!$I$61
Name Preventive_Percent: 'Maintenance Cost Analysis Pivot'!$J$61
Name Slicer_Comments: #N/A
Name Slicer_Department: #N/A
Name Slicer_Department1: #N/A
Name Slicer_Department2: #N/A
Name Slicer_Department3: #N/A
Name Slicer_Department4: #N/A
Name Slicer_Department5: #N/A
Name Slicer_Department6: #N/A
Name Slicer_DowntimeHours: #N/A
Name Slicer_InspectionFreqDays: #N/A
Name Slicer_MaintenanceType: #N/A
Name Slicer_Months__Reported: #N/A
Name Slicer_Months__Reported1: #N/A
Name Slicer_Plant: #N/A
Name Slicer_Plant1: #N/A
Name Slicer_Plant10: #N/A
Name Slicer_Plant11: #N/A
Name Slicer_Plant12: #N/A
Name Slicer_Plant13: #N/A
Name Slicer_Plant14: #N/A
Name Slicer_Plant2: #N/A
Name Slicer_Plant3: #N/A
Name Slicer_Plant4: #N/A
Name Slicer_Plant5: #N/A
Name Slicer_Plant6: #N/A
Name Slicer_Plant7: #N/A
Name Slicer_Plant8: #N/A
Name Slicer_Plant9: #N/A
Name Slicer_Problem: #N/A
Name Slicer_Problem1: #N/A
Name Slicer_Problem2: #N/A
Name Slicer_ReactorType: #N/A
Name Slicer_ReactorType1: #N/A
Name Slicer_ReactorType2: #N/A
Name Slicer_ReactorType3: #N/A
Name Slicer_ReactorType4: #N/A
Name Slicer_ReactorType5: #N/A
Name Slicer_ReactorType6: #N/A
Name Slicer_ReactorType7: #N/A
Name Slicer_Regulation: #N/A
Name Slicer_Reported__Month: #N/A
Name Slicer_Reported__Year: #N/A
Name Slicer_Risk_Category: #N/A
Name Slicer_Vendor: #N/A
Name Slicer_Vendor1: #N/A
Name Slicer_Years__Reported: #N/A

Sheet Workorders Pivot
B3: Open Jobs | C3: Critical Jobs | D3: Total Maintenance Cost | E3: Average Downtime | F3: Average Risk | G3: Vendor Spend | H3: Compliance Rate | I3: Total Work Orders | K3: Total Work Orders | L3: =I4 -> 4496
B4: 1100 | C4: 1147 | D4: 1320732099 | E4: 10.136788 | F4: 49.720418 | G4: 2286020099 | H4: 0.4944395 | I4: 4496 | K4: Open Work Orders | L4: =B4 -> 1100
K5: Critical Work Orders | L5: =C4 -> 1147
K6: Total Maintenace Cost | L6: =D4 -> 1320732099
K7: Average Downtime | L7: =E4 -> 10.136788
K8: Compliance Rate | L8: =H4 -> 0.4944395
K9: Average Risk | L9: =F4 -> 49.720418
K10: Total Vendor Spend | L10: =G4 -> 2286020099

Sheet assets
A1: AssetID | B1: AssetType | C1: CommissionYear
A2: A1000 | B2: Sensor | C2: 1990
A3: A1001 | B3: Pump | C3: 2006
A4: A1002 | B4: Generator | C4: 2019
A5: A1003 | B5: Valve | C5: 2022
A6: A1004 | B6: Valve | C6: 1992
A7: A1005 | B7: Pump | C7: 2015
A8: A1006 | B8: Sensor | C8: 2012
A9: A1007 | B9: Valve | C9: 2017
A10: A1008 | B10: Pump | C10: 2009
A11: A1009 | B11: Valve | C11: 1980
A12: A1010 | B12: Sensor | C12: 2001
A13: A1011 | B13: Generator | C13: 2010
... A301: A1299 | B301: Sensor | C301: 2006

Sheet workorders
A1: WorkOrderID | B1: AssetID | C1: Plant | D1: Vendor | E1: Department | F1: Priority | G1: Status | H1: Problem | I1: RootCause | J1: Reported | K1: Resolved | L1: Days Open | M1: BudgetGBP | N1: ActualGBP | O1: Variance | P1: DowntimeHours | Q1: LostMWh | R1: Risk | S1: Risk Category | T1: Severity | U1: Compliance | V1: AuditScore | W1: Inspector | X1: AssetAge | Y1: ReactorType | Z1: InventoryPart | AA1: InventoryLevel | AB1: ReorderPoint | AC1: ProcurementDelay | AD1: MaintenanceType | AE1: LabourHours | AF1: Technicians | AG1: RadiationZone | AH1: DosemSv | AI1: Regulation | AJ1: FineGBP | AK1: ContractValue | AL1: PaymentStatus | AM1: ForecastCost | AN1: FailureCount | AO1: InspectionFreqDays | AP1: Comments | AQ1: Cost Variance
A2: WO00000 | B2: A1035 | C2: Diablo Canyon | D2: Vendor_23 | E2: Finance | F2: P5 | G2: Cancelled | H2: Inspection Overdue | I2: Design | J2: 45894 | K2: 45921 | L2: 27 | M2: 108964 | N2: 84767 | O2: -24197 | P2: 0 | Q2: 613.1 | R2: 31 | S2: Medium | T2: Low | U2: Compliant | V2: 45 | W2: EMP394 | X2: 12 | Y2: BWR | Z2: P1321 | AA2: 291 | AB2: 95 | AC2: 16 | AD2: Emergency | AE2: 16 | AF2: 5 | AG2: B | AH2: 12.48 | AI2: CNSC | AJ2: 0 | AK2: 284687 | AL2: Paid | AM2: 129708 | AN2: 11 | AO2: 90 | AP2: N/A | AQ2: -24197
A3: WO00002 | B3: A1296 | C3: Bruce A | D3: Vendor_12 | E3: Engineering | F3: P1 | G3: Open | H3: Valve Leak | I3: Unknown | J3: 45095 | K3: 45152 | L3: 57 | M3: 398865 | N3: 388339 | O3: -10526 | P3: 21 | Q3: 175.2 | R3: 84 | S3: High | T3: High | U3: Non-Compliant | V3: 78 | W3: EMP202 | X3: 39 | Y3: BWR | Z3: P1381 | AA3: 6 | AB3: 82 | AC3: 36 | AD3: Emergency | AE3: 12 | AF3: 6 | AG3: D | AH3: 9.25 | AI3: CNSC | AJ3: 0 | AK3: 328285 | AL3: Pending | AM3: 397859 | AN3: 5 | AO3: 90 | AP3: Urgent | AQ3: -10526
A4: WO00003 | B4: A1144 | C4: Diablo Canyon | D4: Vendor_29 | E4: Finance | F4: P3 | G4: Cancelled | H4: Sensor Fault | I4: Unknown | J4: 45392 | K4: 45417 | L4: 25 | M4: 156596 | N4: 136777 | O4: -19819 | P4: 19 | Q4: 109.2 | R4: 31 | S4: Medium | T4: High | U4: Pending | V4: 0 | W4: EMP177 | X4: 16 | Y4: SMR | Z4: P1192 | AA4: 470 | AB4: 48 | AC4: 16 | AD4: Emergency | AE4: 0 | AF4: 2 | AG4: A | AH4: 4.09 | AI4: CNSC | AJ4: 0 | AK4: 538888 | AL4: Overdue | AM4: 150852 | AN4: 12 | AO4: 365 | AP4: Await Docs | AQ4: -19819
A5: WO00004 | B5: A1273 | C5: Heysham 1 | D5: Vendor_29 | E5: Maint | F5: P5 | G5: In Progress | H5: Calibration Drift | I5: Ageing | J5: 45223 | K5: 45272 | L5: 49 | M5: 464250 | N5: 442480 | O5: -21770 | P5: 0 | Q5: 380.8 | R5: 93 | S5: High | T5: High | U5: Compliant | V5: 96 | W5: EMP337 | X5: 44 | Y5: SMR | Z5: P1025 | AA5: 179 | AB5: 107 | AC5: 50 | AD5: Preventive | AE5: 12 | AF5: 2 | AG5: A | AH5: 0.51 | AI5: NRC | AJ5: 44716 | AK5: 17099 | AL5: Pending | AM5: 463311 | AN5: 8 | AO5: 365 | AP5: Repeat Issue | AQ5: -21770
A6: WO00005 | B6: A1286 | C6: Sizewell B | D6: Vendor_7 | E6: Maint | F6: P4 | G6: Open | H6: Valve Leak | I6: Design | J6: 45188 | K6: 45207 | L6: 19 | M6: 211915 | N6: 297787 | O6: 85872 | P6: 21 | Q6: 277.1 | R6: 16 | S6: Low | T6: High | U6: Non-Compliant | V6: 0 | W6: EMP820 | X6: 43 | Y6: AGR | Z6: P1217 | AA6: 24 | AB6: 83 | AC6: 58 | AD6: Corrective | AE6: 2 | AF6: 4 | AG6: D | AH6: 2.04 | AI6: NRC | AJ6: 0 | AK6: 683736 | AL6: Paid | AM6: 225606 | AN6: 8 | AO6: 365 | AP6: No Comment | AQ6: 85872
A7: WO00006 | B7: A1052 | C7: Diablo Canyon | D7: Vendor_19 | E7: Maint | F7: P4 | G7: Open | H7: Inventory Shortage | I7: Unknown | J7: 44751 | K7: 44811 | L7: 60 | M7: 150176 | N7: 239347 | O7: 89171 | P7: 0 | Q7: 357.4 | R7: 10 | S7: Low | T7: Medium | U7: Non-Compliant | V7: 0 | W7: EMP674 | X7: 8 | Y7: PWR | Z7: P1295 | AA7: 108 | AB7: 111 | AC7: 49 | AD7: Emergency | AE7: 4 | AF7: 2 | AG7: C | AH7: 1.51 | AI7: CNSC | AJ7: 0 | AK7: 904267 | AL7: Pending | AM7: 155877 | AN7: 9 | AO7: 180 | AP7: Repeat Issue | AQ7: 89171
A8: WO00008 | B8: A1076 | C8: Bruce A | D8: Vendor_21 | E8: Procurement | F8: P3 | G8: Closed | H8: Inventory Shortage | I8: Unknown | J8: 45497 | K8: 45536 | L8: 39 | M8: 415963 | N8: 392686 | O8: -23277 | P8: 9 | Q8: 125.9 | R8: 40 | S8: Medium | T8: High | U8: Compliant | V8: 44 | W8: EMP808 | X8: 13 | Y8: AGR | Z8: P1051 | AA8: 168 | AB8: 77 | AC8: 8 | AD8: Predictive | AE8: 12 | AF8: 3 | AG8: A | AH8: 7.22 | AI8: STUK | AJ8: 0 | AK8: 588660 | AL8: Overdue | AM8: 398089 | AN8: 0 | AO8: 180 | AP8: Repeat Issue | AQ8: -23277
A9: WO00009 | B9: A1141 | C9: Bruce A | D9: Vendor_13 | E9: Safety | F9: P1 | G9: In Progress | H9: Inventory Shortage | I9: Unknown | J9: 45191 | K9: 45220 | L9: 29 | M9: 371810 | N9: 388498 | O9: 16688 | P9: 0 | Q9: 218.5 | R9: 84 | S9: High | T9: High | U9: Non-Compliant | V9: 0 | W9: EMP439 | X9: 32 | Y9: PHWR | Z9: P1378 | AA9: 31 | AB9: 107 | AC9: 7 | AD9: Emergency | AE9: 16 | AF9: 2 | AG9: C | AH9: 8.7 | AI9: NRC | AJ9: 0 | AK9: 841846 | AL9: Overdue | AM9: 384740 | AN9: 12 | AO9: 180 | AP9: Urgent | AQ9: 16688
A10: WO00010 | B10: A1282 | C10: Heysham 1 | D10: Vendor_24 | E10: Procurement | F10: P4 | G10: Closed | H10: Inspection Overdue | I10: Design | J10: 45484 | K10: 45542 | L10: 58 | M10: 291088 | N10: 262741 | O10: -28347 | P10: 12 | Q10: 90.9 | R10: 34 | S10: Medium | T10: Medium | U10: Pending | V10: 75 | W10: EMP686 | X10: 40 | Y10: BWR | Z10: P1234 | AA10: 261 | AB10: 86 | AC10: 45 | AD10: Predictive | AE10: 0 | AF10: 8 | AG10: C | AH10: 5.76 | AI10: STUK | AJ10: 0 | AK10: 433613 | AL10: Pending | AM10: 294767 | AN10: 7 | AO10: 30 | AP10: Urgent | AQ10: -28347
A11: WO00011 | B11: A1127 | C11: Olkiluoto 3 | D11: Vendor_12 | E11: Procurement | F11: P3 | G11: Closed | H11: Inspection Overdue | I11: Human Error | J11: 45344 | K11: 45356 | L11: 12 | M11: 111295 | N11: 193401 | O11: 82106 | P11: 9 | Q11: 770 | R11: 17 | S11: Low | T11: Medium | U11: Non-Compliant | V11: 0 | W11: EMP173 | X11: 23 | Y11: SMR | Z11: P1452 | AA11: 443 | AB11: 64 | AC11: 2 | AD11: Preventive | AE11: 9 | AF11: 2 | AG11: C | AH11: 16.12 | AI11: NRC | AJ11: 0 | AK11: 697636 | AL11: Pending | AM11: 101513 | AN11: 0 | AO11: 180 | AP11: No Comment | AQ11: 82106
A12: WO00012 | B12: A1170 | C12: Sizewell B | D12: Vendor_30 | E12: Finance | F12: P1 | G12: In Progress | H12: Pump Failure | I12: Design | J12: 45075 | K12: 45073 | L12: -2 | M12: 405250 | N12: 426610 | O12: 21360 | P12: 19 | Q12: 239.3 | R12: 49 | S12: Medium | T12: High | U12: Compliant | V12: 0 | W12: EMP696 | X12: 38 | Y12: BWR | Z12: P1448 | AA12: -4 | AB12: 25 | AC12: 52 | AD12: Preventive | AE12: 9 | AF12: 8 | AG12: A | AH12: 7.74 | AI12: STUK | AJ12: 0 | AK12: 290647 | AL12: Pending | AM12: 448942 | AN12: 1 | AO12: 180 | AP12: Urgent | AQ12: 21360
A13: WO00013 | B13: A1002 | C13: Heysham 1 | D13: Vendor_4 | E13: Safety | F13: P1 | G13: In Progress | H13: Valve Leak | I13: Ageing | J13: 45317 | K13: 45337 | L13: 20 | M13: 178853 | N13: 196379 | O13: 17526 | P13: 9 | Q13: 263.2 | R13: 26 | S13: Low | T13: High | U13: Pending | V13: 0 | W13: EMP314 | X13: 15 | Y13: SMR | Z13: P1060 | AA13: 107 | AB13: 77 | AC13: 0 | AD13: Corrective | AE13: 16 | AF13: 8 | AG13: B | AH13: 5.11 | AI13: ONR | AJ13: 0 | AK13: 566027 | AL13: Pending | AM13: 209599 | AN13: 7 | AO13: 365 | AP13: Repeat Issue | AQ13: 17526
... A4497: WO04999 | B4497: A1275 | C4497: Olkiluoto 3 | D4497: Vendor_27 | E4497: Ops | F4497: P3 | G4497: Open | H4497: Pump Failure | I4497: Vendor Delay | J4497: 45252 | K4497: 45293 | L4497: 41 | M4497: 198800 | N4497: 304137 | O4497: 105337 | P4497: 19 | Q4497: 292.6 | R4497: 82 | S4497: High | T4497: Low | U4497: Compliant | V4497: 0 | W4497: EMP143 | X4497: 29 | Y4497: PHWR | Z4497: P1258 | AA4497: 485 | AB4497: 46 | AC4497: 82 | AD4497: Predictive | AE4497: 4 | AF4497: 7 | AG4497: C | AH4497: 8.85 | AI4497: CNSC | AJ4497: 0 | AK4497: 181186 | AL4497: Overdue | AM4497: 196295 | AN4497: 2 | AO4497: 365 | AP4497: Await Docs | AQ4497: 105337

Sheet vendors
A1: Column1 | B1: Column2
A2: Vendor | B2: Country
A3: Vendor_1 | B3: United Kingdom
A4: Vendor_2 | B4: United States of America
A5: Vendor_3 | B5: United Kingdom
A6: Vendor_4 | B6: United States of America
A7: Vendor_5 | B7: Finland
A8: Vendor_6 | B8: Canada
A9: Vendor_7 | B9: United Kingdom
A10: Vendor_8 | B10: Canada
A11: Vendor_9 | B11: United States of America
A12: Vendor_10 | B12: Canada
... A32: Vendor_30 | B32: United States of America

Sheet Working 1
A3: Plant | B3: Sum of DowntimeHours
A4: Bruce A | B4: 7263
A5: Diablo Canyon | B5: 7882
A6: Heysham 1 | B6: 8367
A7: Olkiluoto 3 | B7: 7173
A8: Sizewell B | B8: 7657
A9: Torness | B9: 7233
A10: Grand Total | B10: 45575
A21: Severity | B21: Count of WorkOrderID
A22: Critical | B22: 1147
A23: Medium | B23: 1124
A24: High | B24: 1122
A25: Low | B25: 1103
A26: Grand Total | B26: 4496
A40: Status | B40: Count of WorkOrderID
A41: Cancelled | B41: 1158
A42: Closed | B42: 1134
A43: In Progress | B43: 1104
A44: Open | B44: 1100
A45: Grand Total | B45: 4496
A55: Row Labels | B55: Sum of ActualGBP
A56: 2022 | B56: 343277558
A57: Jan | B57: 30888247
A58: Feb | B58: 24178509
A59: Mar | B59: 28991937
A60: Apr | B60: 28588602
A61: May | B61: 33393993
A62: Jun | B62: 29787264
A63: Jul | B63: 24008335
A64: Aug | B64: 32753127
A65: Sep | B65: 26593062
A66: Oct | B66: 23110896
A67: Nov | B67: 31824398
... A107: Grand Total | B107: 1320732099
A111: Department | B111: Sum of ActualGBP | D111: Department | E111: Department Spend
A112: Engineering | B112: 209864349 | D112: {=A112:B117} -> Engineering | E112: 209864349
A113: Finance | B113: 212818767 | D113: Finance | E113: 212818767
A114: Maint | B114: 234434427 | D114: Maint | E114: 234434427
A115: Ops | B115: 216550039 | D115: Ops | E115: 216550039
A116: Procurement | B116: 227877020 | D116: Procurement | E116: 227877020
...

Sheet Executive KPI Dashboard
L1: Executive KPI Dashboard

Sheet Emergency cost
A3: Row Labels | B3: Emergency Cost | C3: Preventive Cost | D3: Emergency Cost % | E3: Preventive Cost %
A4: Bruce A | B4: 49328606 | C4: 53631225 | D4: 0.23521982 | E4: 0.25573654
A5: Diablo Canyon | B5: 56706713 | C5: 51206841 | D5: 0.24435084 | E5: 0.22065173
A6: Heysham 1 | B6: 62927377 | C6: 66468737 | D6: 0.25857878 | E6: 0.2731308
A7: Olkiluoto 3 | B7: 46951017 | C7: 54970808 | D7: 0.22927791 | E7: 0.2684413
A8: Sizewell B | B8: 57790094 | C8: 57119685 | D8: 0.26122276 | E8: 0.25819238
A9: Torness | B9: 50398611 | C9: 50154585 | D9: 0.24047104 | E9: 0.2393067
A10: Grand Total | B10: 324102418 | C10: 333551881 | D10: 0.24539603 | E10: 0.25255075

Sheet Maintenance Cost Analysis Pivot
A3: Row Labels | B3: Sum of ActualGBP
A4: Bruce A | B4: 209712797
A5: Diablo Canyon | B5: 232070877
A6: Heysham 1 | B6: 243358630
A7: Olkiluoto 3 | B7: 204777762
A8: Sizewell B | B8: 221229166
A9: Torness | B9: 209582867
A14: Row Labels | B14: Sum of BudgetGBP | C14: Sum of ActualGBP | D14: Sum of Variance | F14: Department | G14: Budget | H14: Actual | I14: Variance
A15: Engineering | B15: 181747965 | C15: 209864349 | D15: 28116384 | F15: {=A15:D20} -> Engineering | G15: 181747965 | H15: 209864349 | I15: 28116384
A16: Finance | B16: 184611294 | C16: 212818767 | D16: 28207473 | F16: Finance | G16: 184611294 | H16: 212818767 | I16: 28207473
A17: Maint | B17: 203256946 | C17: 234434427 | D17: 31177481 | F17: Maint | G17: 203256946 | H17: 234434427 | I17: 31177481
A18: Ops | B18: 187092616 | C18: 216550039 | D18: 29457423 | F18: Ops | G18: 187092616 | H18: 216550039 | I18: 29457423
A19: Procurement | B19: 196447870 | C19: 227877020 | D19: 31429150 | F19: Procurement | G19: 196447870 | H19: 227877020 | I19: 31429150
A20: Safety | B20: 190348244 | C20: 219187497 | D20: 28839253 | F20: Safety | G20: 190348244 | H20: 219187497 | I20: 28839253
A32: Month | B32: Maintenance Cost
A33: Jan | B33: 123053507
A34: Feb | B34: 111733517
A35: Mar | B35: 120797052
A36: Apr | B36: 108527711
A37: May | B37: 118063587
A38: Jun | B38: 123791918
A39: Jul | B39: 114859012
A40: Aug | B40: 118464105
A41: Sep | B41: 111532461
A42: Oct | B42: 110406938
A43: Nov | B43: 78776087
A44: Dec | B44: 80726204
A51: Plant | B51: Sum of ActualGBP | C51: Emergency Cost | D51: Preventive Cost | E51: Preventive Cost % | F51: Emergency Cost % | H51: Emergency Cost | I51: Preventive Cost | J51: Preventive Cost % | K51: Emergency Cost %
A52: Bruce A | B52: 209712797 | C52: 49328606 | D52: 53631225 | E52: 0.25573654 | F52: 0.23521982 | H52: =C58 -> 324102418 | I52: =D58 -> 333551881 | J52: =E58 -> 0.25255075 | K52: =F58 -> 0.24539603
A53: Diablo Canyon | B53: 232070877 | C53: 56706713 | D53: 51206841 | E53: 0.22065173 | F53: 0.24435084
A54: Heysham 1 | B54: 243358630 | C54: 62927377 | D54: 66468737 | E54: 0.2731308 | F54: 0.25857878
A55: Olkiluoto 3 | B55: 204777762 | C55: 46951017 | D55: 54970808 | E55: 0.2684413 | F55: 0.22927791
A56: Sizewell B | B56: 221229166 | C56: 57790094 | D56: 57119685 | E56: 0.25819238 | F56: 0.26122276
A57: Torness | B57: 209582867 | C57: 50398611 | D57: 50154585 | E57: 0.2393067 | F57: 0.24047104
A58: Grand Total | B58: 1320732099 | C58: 324102418 | D58: 333551881 | E58: 0.25255075 | F58: 0.24539603

Sheet Maintenance Cost Dashboard
G1: Maintenance Cost Analysis Dashboard

Sheet Equipment Reliability Pivot
A2: Average of FailureCount | B2: Average of AssetAge | C2: Average of DowntimeHours | F2: Average Failure Count | G2: =A3 -> 5.9432829
A3: 5.9432829 | B3: 22.829404 | C3: 10.136788 | F3: Average Asset Age | G3: =B3 -> 22.829404
F4: Average Downtime | G4: =C3 -> 10.136788
A7: Assset ID | B7: Sum of DowntimeHours | C7: Sum of LostMWh | F7: Top 10 Worst Asset by Lost MWh
A8: A1221 | B8: 35 | C8: 2100.7 | F8: =A8 -> A1221 | G8: =VLOOKUP(F8,assets!$A:$B,2,FALSE) -> Generator | H8: =G8 -> Generator
A9: A1079 | B9: 41 | C9: 1643.2 | F9: =A9 -> A1079 | G9: =VLOOKUP(F9,assets!$A:$B,2,FALSE) -> Valve | H9: =G9 -> Valve
A10: A1095 | B10: 41 | C10: 1585.8 | F10: =A10 -> A1095 | G10: =VLOOKUP(F10,assets!$A:$B,2,FALSE) -> Pump | H10: =G10 -> Pump
A11: A1212 | B11: 14 | C11: 1575.1 | F11: =A11 -> A1212 | G11: =VLOOKUP(F11,assets!$A:$B,2,FALSE) -> Generator | H11: =G11 -> Generator
A12: A1191 | B12: 16 | C12: 1570.9 | F12: =A12 -> A1191 | G12: =VLOOKUP(F12,assets!$A:$B,2,FALSE) -> Pump | H12: =G12 -> Pump
A13: A1107 | B13: 28 | C13: 1465.7 | F13: =A13 -> A1107 | G13: =VLOOKUP(F13,assets!$A:$B,2,FALSE) -> Sensor | H13: =G13 -> Sensor
A14: A1070 | B14: 35 | C14: 1459.9 | F14: =A14 -> A1070 | G14: =VLOOKUP(F14,assets!$A:$B,2,FALSE) -> Valve | H14: =G14 -> Valve
A15: A1108 | B15: 6 | C15: 1389.7 | F15: =A15 -> A1108 | G15: =VLOOKUP(F15,assets!$A:$B,2,FALSE) -> Pump | H15: =G15 -> Pump
A16: A1133 | B16: 37 | C16: 1337 | F16: =A16 -> A1133 | G16: =VLOOKUP(F16,assets!$A:$B,2,FALSE) -> Sensor | H16: =G16 -> Sensor
A17: A1293 | B17: 28 | C17: 1156.4 | F17: =A17 -> A1293 | G17: =VLOOKUP(F17,assets!$A:$B,2,FALSE) -> Pump | H17: =G17 -> Pump
A18: Grand Total | B18: 281 | C18: 15284.4
A21: Count of Comments | B21: Column Labels
A22: Row Labels | B22: Repeat Issue | C22: Grand Total | F22: Top 10 Worst Asset by Repeat Issues
A23: A1148 | B23: 2 | C23: 2 | F23: =A23 -> A1148 | G23: =VLOOKUP(F23,assets!$A:$B,2,FALSE) -> Generator | H23: =G23 -> Generator
A24: A1211 | B24: 1 | C24: 1 | F24: =A24 -> A1211 | G24: =VLOOKUP(F24,assets!$A:$B,2,FALSE) -> Generator | H24: =G24 -> Generator
A25: A1009 | B25: 1 | C25: 1 | F25: =A25 -> A1009 | G25: =VLOOKUP(F25,assets!$A:$B,2,FALSE) -> Valve | H25: =G25 -> Valve
A26: A1262 | B26: 1 | C26: 1 | F26: =A26 -> A1262 | G26: =VLOOKUP(F26,assets!$A:$B,2,FALSE) -> Generator | H26: =G26 -> Generator
A27: A1086 | B27: 1 | C27: 1 | F27: =A27 -> A1086 | G27: =VLOOKUP(F27,assets!$A:$B,2,FALSE) -> Generator | H27: =G27 -> Generator
A28: A1169 | B28: 1 | C28: 1 | F28: =A28 -> A1169 | G28: =VLOOKUP(F28,assets!$A:$B,2,FALSE) -> Valve | H28: =G28 -> Valve
A29: A1089 | B29: 1 | C29: 1 | F29: =A29 -> A1089 | G29: =VLOOKUP(F29,assets!$A:$B,2,FALSE) -> Generator | H29: =G29 -> Generator
A30: A1214 | B30: 1 | C30: 1 | F30: =A30 -> A1214 | G30: =VLOOKUP(F30,assets!$A:$B,2,FALSE) -> Valve | H30: =G30 -> Valve
A31: A1095 | B31: 1 | C31: 1 | F31: =A31 -> A1095 | G31: =VLOOKUP(F31,assets!$A:$B,2,FALSE) -> Pump | H31: =G31 -> Pump
A32: A1045 | B32: 1 | C32: 1 | F32: =A32 -> A1045 | G32: =VLOOKUP(F32,assets!$A:$B,2,FALSE) -> Sensor | H32: =G32 -> Sensor
A33: A1102 | B33: 1 | C33: 1 | F33: =A33 -> A1102 | G33: =VLOOKUP(F33,assets!$A:$B,2,FALSE) -> Pump | H33: =G33 -> Pump
A34: A1162 | B34: 1 | C34: 1 | F34: =A34 -> A1162 | G34: =VLOOKUP(F34,assets!$A:$B,2,FALSE) -> Valve | H34: =G34 -> Valve
... A36: A1188 | B36: 1 | C36: 1 | F36: =A36 -> A1188 | G36: =VLOOKUP(F36,assets!$A:$B,2,FALSE) -> Generator | H36: =G36 -> Generator
A37: A1105 | B37: 1 | C37: 1
A38: A1212 | B38: 1 | C38: 1 | G38: =_xlfn.XLOOKUP(F23,assets!A:A,assets!B:B,"Not Found") -> Generator
A39: A1117 | B39: 1 | C39: 1
A40: A1257 | B40: 1 | C40: 1
A41: A1122 | B41: 1 | C41: 1
A42: A1263 | B42: 1 | C42: 1
A43: A1282 | B43: 1 | C43: 1
A44: A1287 | B44: 1 | C44: 1
A45: A1296 | B45: 1 | C45: 1
A46: A1153 | B46: 1 | C46: 1
...

Sheet Equipment Reliability Dashboard
F2: Equipment Reliability Dashboard
B14: Top 10 Worst Asset by Lost MWh | H14: Top 10 Worst Asset by Repeat Issues
B15: Asset | H15: Asset
B16: ='Equipment Reliability Pivot'!H8 -> Generator | H16: ='Equipment Reliability Pivot'!H23 -> Generator
B17: ='Equipment Reliability Pivot'!H9 -> Valve | H17: ='Equipment Reliability Pivot'!H24 -> Generator
B18: ='Equipment Reliability Pivot'!H10 -> Pump | H18: ='Equipment Reliability Pivot'!H25 -> Valve
B19: ='Equipment Reliability Pivot'!H11 -> Generator | H19: ='Equipment Reliability Pivot'!H26 -> Generator
B20: ='Equipment Reliability Pivot'!H12 -> Pump | H20: ='Equipment Reliability Pivot'!H27 -> Generator
B21: ='Equipment Reliability Pivot'!H13 -> Sensor | H21: ='Equipment Reliability Pivot'!H28 -> Valve
B22: ='Equipment Reliability Pivot'!H14 -> Valve | H22: ='Equipment Reliability Pivot'!H29 -> Generator
B23: ='Equipment Reliability Pivot'!H15 -> Pump | H23: ='Equipment Reliability Pivot'!H30 -> Valve
B24: ='Equipment Reliability Pivot'!H16 -> Sensor | H24: ='Equipment Reliability Pivot'!H31 -> Pump
B25: ='Equipment Reliability Pivot'!H17 -> Pump | H25: ='Equipment Reliability Pivot'!H32 -> Sensor
B35: Asset | C35: Maintenance Cost
B36: ='Equipment Reliability Pivot'!J148 -> Sensor | C36: ='Equipment Reliability Pivot'!H148 -> 2655664
B37: ='Equipment Reliability Pivot'!J149 -> Generator | C37: ='Equipment Reliability Pivot'!H149 -> 2184460
B38: ='Equipment Reliability Pivot'!J150 -> Pump | C38: ='Equipment Reliability Pivot'!H150 -> 2096082
B39: ='Equipment Reliability Pivot'!J151 -> Pump | C39: ='Equipment Reliability Pivot'!H151 -> 1924336
B40: ='Equipment Reliability Pivot'!J152 -> Pump | C40: ='Equipment Reliability Pivot'!H152 -> 1899300
B41: ='Equipment Reliability Pivot'!J153 -> Generator | C41: ='Equipment Reliability Pivot'!H153 -> 2606079
B42: ='Equipment Reliability Pivot'!J154 -> Valve | C42: ='Equipment Reliability Pivot'!H154 -> 2557599
B43: ='Equipment Reliability Pivot'!J155 -> Valve | C43: ='Equipment Reliability Pivot'!H155 -> 2514973
B44: ='Equipment Reliability Pivot'!J156 -> Sensor | C44: ='Equipment Reliability Pivot'!H156 -> 2432873
B45: ='Equipment Reliability Pivot'!J157 -> Generator | C45: ='Equipment Reliability Pivot'!H157 -> 2219052
B46: ='Equipment Reliability Pivot'!J158 -> Pump | C46: ='Equipment Reliability Pivot'!H158 -> 2996854
B47: ='Equipment Reliability Pivot'!J159 -> Pump | C47: ='Equipment Reliability Pivot'!H159 -> 2966518
... B65: ='Equipment Reliability Pivot'!J177 -> Valve | C65: ='Equipment Reliability Pivot'!H177 -> 2046937

Sheet Vendor Performance 
A3: Average Delay (Days) | B3: Vendor Spend | C3: Average of ContractValue | E3: Average Delay Days | F3: Vendor Spend | G3: Contract value
A4: 42.84097 | B4: 2286020099 | C4: 508456.43 | E4: =TEXT(A4,"0.0")&" Days" -> 42.8 Days | F4: =B4 -> 2286020099 | G4: =C4 -> 508456.43
A9: Late Deliveries | B9: Late Deliveries % | E9: Late Deliveries %
A10: 4304 | B10: 0.95729537 | E10: =B10 -> 0.95729537
A15: Vendor | B15: Vendor Spend
A16: Vendor_1 | B16: 11263243
A17: Vendor_10 | B17: 10990825
A18: Vendor_11 | B18: 11428945
A19: Vendor_12 | B19: 11587974
A20: Vendor_13 | B20: 14397448
A21: Vendor_14 | B21: 12926613
A22: Vendor_15 | B22: 6082532
A23: Vendor_16 | B23: 13177295
A24: Vendor_17 | B24: 13387505
A25: Vendor_18 | B25: 12831401
A26: Vendor_19 | B26: 14273625
A27: Vendor_2 | B27: 7322609
... A45: Vendor_9 | B45: 9117300
A51: Delay | B51: Vendor Spend | D51: Delay | E51: Spend
A52: -3 | B52: 2057834 | D52: =A52 -> -3 | E52: =B52 -> 2057834
A53: -2 | B53: 1222054 | D53: =A53 -> -2 | E53: =B53 -> 1222054
A54: -1 | B54: 5523796 | D54: =A54 -> -1 | E54: =B54 -> 5523796
A55: 0 | B55: 1679068 | D55: =A55 -> 0 | E55: =B55 -> 1679068
A56: 1 | B56: 3036117 | D56: =A56 -> 1 | E56: =B56 -> 3036117
A57: 2 | B57: 1462205 | D57: =A57 -> 2 | E57: =B57 -> 1462205
A58: 3 | B58: 2838091 | D58: =A58 -> 3 | E58: =B58 -> 2838091
A59: 4 | B59: 5956917 | D59: =A59 -> 4 | E59: =B59 -> 5956917
A60: 5 | B60: 3064153 | D60: =A60 -> 5 | E60: =B60 -> 3064153
A61: 6 | B61: 6236798 | D61: =A61 -> 6 | E61: =B61 -> 6236798
A62: 7 | B62: 4820018 | D62: =A62 -> 7 | E62: =B62 -> 4820018
A63: 8 | B63: 6074429 | D63: =A63 -> 8 | E63: =B63 -> 6074429
... A145: 90 | B145: 5458652 | D145: =A145 -> 90 | E145: =B145 -> 5458652
A149: Vendor | B149: Average Delay (Days) | D149: Vendor | E149: Country | F149: Delay
A150: Vendor_1 | B150: 38.8 | D150: =A150 -> Vendor_1 | E150: =_xlfn.XLOOKUP(D150,vendors!A:A,vendors!B:B,"Not Found") -> United Kingdom | F150: =B150 -> 38.8
A151: Vendor_10 | B151: 39.92 | D151: =A151 -> Vendor_10 | E151: =_xlfn.XLOOKUP(D151,vendors!A:A,vendors!B:B,"Not Found") -> Canada | F151: =B151 -> 39.92
A152: Vendor_11 | B152: 37.740741 | D152: =A152 -> Vendor_11 | E152: =_xlfn.XLOOKUP(D152,vendors!A:A,vendors!B:B,"Not Found") -> United States of America | F152: =B152 -> 37.740741
A153: Vendor_12 | B153: 35.64 | D153: =A153 -> Vendor_12 | E153: =_xlfn.XLOOKUP(D153,vendors!A:A,vendors!B:B,"Not Found") -> Canada | F153: =B153 -> 35.64
A154: Vendor_13 | B154: 46.92 | D154: =A154 -> Vendor_13 | E154: =_xlfn.XLOOKUP(D154,vendors!A:A,vendors!B:B,"Not Found") -> United Kingdom | F154: =B154 -> 46.92
A155: Vendor_14 | B155: 41.380952 | D155: =A155 -> Vendor_14 | E155: =_xlfn.XLOOKUP(D155,vendors!A:A,vendors!B:B,"Not Found") -> United States of America | F155: =B155 -> 41.380952
A156: Vendor_15 | B156: 44.357143 | D156: =A156 -> Vendor_15 | E156: =_xlfn.XLOOKUP(D156,vendors!A:A,vendors!B:B,"Not Found") -> United Kingdom | F156: =B156 -> 44.357143
...

Sheet Vendor Performance Scorecard
F2: Vendor Performance Scorecard
L58: Top 10 Vendors | P58: Vendors Requiring Performance Improvement
D59: Vendor | E59: Vendor Spend | F59: Late Deliveries % | G59: Average Delay (Days) | H59: Compliance % | I59: Score | J59: Rating | L59: Vendor | M59: Vendor Spend | P59: Vendor | Q59: Late Deliveries %
D60: ='Vendor Performance '!H257 -> Vendor_13 | E60: ='Vendor Performance '!I257 -> 89147397 | F60: ='Vendor Performance '!J257 -> 0.97076023 | G60: ='Vendor Performance '!K257 -> 43.385965 | H60: ='Vendor Performance '!L257 -> 0.49122807 | I60: ='Vendor Performance '!Q257 -> 0.41397494 | J60: ='Vendor Performance '!R257 -> Poor | L60: ='Vendor Performance '!H187 -> Vendor_13 | M60: ='Vendor Performance '!I187 -> 89147397 | P60: ='Vendor Performance '!H222 -> Vendor_2 | Q60: ='Vendor Performance '!I222 -> 0.99253731
D61: ='Vendor Performance '!H258 -> Vendor_23 | E61: ='Vendor Performance '!I258 -> 89034535 | F61: ='Vendor Performance '!J258 -> 0.97142857 | G61: ='Vendor Performance '!K258 -> 42.611429 | H61: ='Vendor Performance '!L258 -> 0.43428571 | I61: ='Vendor Performance '!Q258 -> 0.39628231 | J61: ='Vendor Performance '!R258 -> Poor | L61: ='Vendor Performance '!H188 -> Vendor_23 | M61: ='Vendor Performance '!I188 -> 89034535 | P61: ='Vendor Performance '!H223 -> Vendor_28 | Q61: ='Vendor Performance '!I223 -> 0.98136646
D62: ='Vendor Performance '!H259 -> Vendor_8 | E62: ='Vendor Performance '!I259 -> 87468749 | F62: ='Vendor Performance '!J259 -> 0.95857988 | G62: ='Vendor Performance '!K259 -> 44.816568 | H62: ='Vendor Performance '!L259 -> 0.55029586 | I62: ='Vendor Performance '!Q259 -> 0.42781987 | J62: ='Vendor Performance '!R259 -> Poor | L62: ='Vendor Performance '!H189 -> Vendor_8 | M62: ='Vendor Performance '!I189 -> 87468749 | P62: ='Vendor Performance '!H224 -> Vendor_7 | Q62: ='Vendor Performance '!I224 -> 0.98
D63: ='Vendor Performance '!H260 -> Vendor_27 | E63: ='Vendor Performance '!I260 -> 86695717 | F63: ='Vendor Performance '!J260 -> 0.95541401 | G63: ='Vendor Performance '!K260 -> 40.955414 | H63: ='Vendor Performance '!L260 -> 0.54140127 | I63: ='Vendor Performance '!Q260 -> 0.43082671 | J63: ='Vendor Performance '!R260 -> Poor | L63: ='Vendor Performance '!H190 -> Vendor_27 | M63: ='Vendor Performance '!I190 -> 86695717 | P63: ='Vendor Performance '!H225 -> Vendor_9 | Q63: ='Vendor Performance '!I225 -> 0.975
D64: ='Vendor Performance '!H261 -> Vendor_1 | E64: ='Vendor Performance '!I261 -> 85232426 | F64: ='Vendor Performance '!J261 -> 0.96319018 | G64: ='Vendor Performance '!K261 -> 42.294479 | H64: ='Vendor Performance '!L261 -> 0.50920245 | I64: ='Vendor Performance '!Q261 -> 0.41961952 | J64: ='Vendor Performance '!R261 -> Poor | L64: ='Vendor Performance '!H191 -> Vendor_1 | M64: ='Vendor Performance '!I191 -> 85232426 | P64: ='Vendor Performance '!H226 -> Vendor_23 | Q64: ='Vendor Performance '!I226 -> 0.97142857
D65: ='Vendor Performance '!H262 -> Vendor_5 | E65: ='Vendor Performance '!I262 -> 80976120 | F65: ='Vendor Performance '!J262 -> 0.94193548 | G65: ='Vendor Performance '!K262 -> 43.03871 | H65: ='Vendor Performance '!L262 -> 0.47741935 | I65: ='Vendor Performance '!Q262 -> 0.42279608 | J65: ='Vendor Performance '!R262 -> Poor | L65: ='Vendor Performance '!H192 -> Vendor_5 | M65: ='Vendor Performance '!I192 -> 80976120 | P65: ='Vendor Performance '!H227 -> Vendor_13 | Q65: ='Vendor Performance '!I227 -> 0.97076023
D66: ='Vendor Performance '!H263 -> Vendor_9 | E66: ='Vendor Performance '!I263 -> 80497730 | F66: ='Vendor Performance '!J263 -> 0.975 | G66: ='Vendor Performance '!K263 -> 42.3125 | H66: ='Vendor Performance '!L263 -> 0.425 | I66: ='Vendor Performance '!Q263 -> 0.39414627 | J66: ='Vendor Performance '!R263 -> Poor | L66: ='Vendor Performance '!H193 -> Vendor_9 | M66: ='Vendor Performance '!I193 -> 80497730 | P66: ='Vendor Performance '!H228 -> Vendor_18 | Q66: ='Vendor Performance '!I228 -> 0.96969697
D67: ='Vendor Performance '!H264 -> Vendor_12 | E67: ='Vendor Performance '!I264 -> 80462105 | F67: ='Vendor Performance '!J264 -> 0.94904459 | G67: ='Vendor Performance '!K264 -> 40.840764 | H67: ='Vendor Performance '!L264 -> 0.49044586 | I67: ='Vendor Performance '!Q264 -> 0.42000272 | J67: ='Vendor Performance '!R264 -> Poor | L67: ='Vendor Performance '!H194 -> Vendor_12 | M67: ='Vendor Performance '!I194 -> 80462105 | P67: ='Vendor Performance '!H229 -> Vendor_15 | Q67: ='Vendor Performance '!I229 -> 0.96428571
D68: ='Vendor Performance '!H265 -> Vendor_28 | E68: ='Vendor Performance '!I265 -> 80233265 | F68: ='Vendor Performance '!J265 -> 0.98136646 | G68: ='Vendor Performance '!K265 -> 46.416149 | H68: ='Vendor Performance '!L265 -> 0.48447205 | I68: ='Vendor Performance '!Q265 -> 0.40686088 | J68: ='Vendor Performance '!R265 -> Poor | L68: ='Vendor Performance '!H195 -> Vendor_28 | M68: ='Vendor Performance '!I195 -> 80233265 | P68: ='Vendor Performance '!H230 -> Vendor_17 | Q68: ='Vendor Performance '!I230 -> 0.96323529
D69: ='Vendor Performance '!H266 -> Vendor_14 | E69: ='Vendor Performance '!I266 -> 77577869 | F69: ='Vendor Performance '!J266 -> 0.95333333 | G69: ='Vendor Performance '!K266 -> 40.353333 | H69: ='Vendor Performance '!L266 -> 0.52666667 | I69: ='Vendor Performance '!Q266 -> 0.42450726 | J69: ='Vendor Performance '!R266 -> Poor | L69: ='Vendor Performance '!H196 -> Vendor_14 | M69: ='Vendor Performance '!I196 -> 77577869 | P69: ='Vendor Performance '!H231 -> Vendor_1 | Q69: ='Vendor Performance '!I231 -> 0.96319018
D70: ='Vendor Performance '!H267 -> Vendor_6 | E70: ='Vendor Performance '!I267 -> 76299591 | F70: ='Vendor Performance '!J267 -> 0.94904459 | G70: ='Vendor Performance '!K267 -> 40.458599 | H70: ='Vendor Performance '!L267 -> 0.50955414 | I70: ='Vendor Performance '!Q267 -> 0.43277238 | J70: ='Vendor Performance '!R267 -> Poor
D71: ='Vendor Performance '!H268 -> Vendor_4 | E71: ='Vendor Performance '!I268 -> 76222551 | F71: ='Vendor Performance '!J268 -> 0.95945946 | G71: ='Vendor Performance '!K268 -> 43.310811 | H71: ='Vendor Performance '!L268 -> 0.56756757 | I71: ='Vendor Performance '!Q268 -> 0.44214478 | J71: ='Vendor Performance '!R268 -> Poor
D72: ='Vendor Performance '!H269 -> Vendor_26 | E72: ='Vendor Performance '!I269 -> 76085899 | F72: ='Vendor Performance '!J269 -> 0.94736842 | G72: ='Vendor Performance '!K269 -> 41.75 | H72: ='Vendor Performance '!L269 -> 0.51315789 | I72: ='Vendor Performance '!Q269 -> 0.43027493 | J72: ='Vendor Performance '!R269 -> Poor
D73: ='Vendor Performance '!H270 -> Vendor_20 | E73: ='Vendor Performance '!I270 -> 75920944 | F73: ='Vendor Performance '!J270 -> 0.95862069 | G73: ='Vendor Performance '!K270 -> 43.137931 | H73: ='Vendor Performance '!L270 -> 0.44827586 | I73: ='Vendor Performance '!Q270 -> 0.41213132 | J73: ='Vendor Performance '!R270 -> Poor
D74: ='Vendor Performance '!H271 -> Vendor_7 | E74: ='Vendor Performance '!I271 -> 75731281 | F74: ='Vendor Performance '!J271 -> 0.98 | G74: ='Vendor Performance '!K271 -> 43.393333 | H74: ='Vendor Performance '!L271 -> 0.56 | I74: ='Vendor Performance '!Q271 -> 0.42927658 | J74: ='Vendor Performance '!R271 -> Poor
D75: ='Vendor Performance '!H272 -> Vendor_24 | E75: ='Vendor Performance '!I272 -> 75472651 | F75: ='Vendor Performance '!J272 -> 0.94482759 | G75: ='Vendor Performance '!K272 -> 42.765517 | H75: ='Vendor Performance '!L272 -> 0.44137931 | I75: ='Vendor Performance '!Q272 -> 0.41586728 | J75: ='Vendor Performance '!R272 -> Poor
D76: ='Vendor Performance '!H273 -> Vendor_29 | E76: ='Vendor Performance '!I273 -> 74984523 | F76: ='Vendor Performance '!J273 -> 0.95774648 | G76: ='Vendor Performance '!K273 -> 42.28169 | H76: ='Vendor Performance '!L273 -> 0.54929577 | I76: ='Vendor Performance '!Q273 -> 0.44284902 | J76: ='Vendor Performance '!R273 -> Poor
D77: ='Vendor Performance '!H274 -> Vendor_15 | E77: ='Vendor Performance '!I274 -> 74193644 | F77: ='Vendor Performance '!J274 -> 0.96428571 | G77: ='Vendor Performance '!K274 -> 47.342857 | H77: ='Vendor Performance '!L274 -> 0.52857143 | I77: ='Vendor Performance '!Q274 -> 0.42039098 | J77: ='Vendor Performance '!R274 -> Poor
D78: ='Vendor Performance '!H275 -> Vendor_17 | E78: ='Vendor Performance '!I275 -> 73794982 | F78: ='Vendor Performance '!J275 -> 0.96323529 | G78: ='Vendor Performance '!K275 -> 41.169118 | H78: ='Vendor Performance '!L275 -> 0.43382353 | I78: ='Vendor Performance '!Q275 -> 0.39249756 | J78: ='Vendor Performance '!R275 -> Poor
D79: ='Vendor Performance '!H276 -> Vendor_30 | E79: ='Vendor Performance '!I276 -> 73664406 | F79: ='Vendor Performance '!J276 -> 0.92361111 | G79: ='Vendor Performance '!K276 -> 43.243056 | H79: ='Vendor Performance '!L276 -> 0.49305556 | I79: ='Vendor Performance '!Q276 -> 0.43177463 | J79: ='Vendor Performance '!R276 -> Poor
D80: ='Vendor Performance '!H277 -> Vendor_16 | E80: ='Vendor Performance '!I277 -> 73170841 | F80: ='Vendor Performance '!J277 -> 0.91608392 | G80: ='Vendor Performance '!K277 -> 41.594406 | H80: ='Vendor Performance '!L277 -> 0.46153846 | I80: ='Vendor Performance '!Q277 -> 0.41937622 | J80: ='Vendor Performance '!R277 -> Poor
D81: ='Vendor Performance '!H278 -> Vendor_19 | E81: ='Vendor Performance '!I278 -> 72891424 | F81: ='Vendor Performance '!J278 -> 0.95804196 | G81: ='Vendor Performance '!K278 -> 41.559441 | H81: ='Vendor Performance '!L278 -> 0.53846154 | I81: ='Vendor Performance '!Q278 -> 0.42789898 | J81: ='Vendor Performance '!R278 -> Poor
... D89: ='Vendor Performance '!H286 -> Vendor_18 | E89: ='Vendor Performance '!I286 -> 59995520 | F89: ='Vendor Performance '!J286 -> 0.96969697 | G89: ='Vendor Performance '!K286 -> 44.772727 | H89: ='Vendor Performance '!L286 -> 0.4469697 | I89: ='Vendor Performance '!Q286 -> 0.39713637 | J89: ='Vendor Performance '!R286 -> Poor

Sheet Regulatory  Compliance Pivot 
A2: Row Labels | B2: Count of Compliance
A3: Compliant | B3: 0.4944395 | D3: Compliance % | E3: =B3 -> 0.4944395
A4: Non-Compliant | B4: 0.25177936
A5: Pending | B5: 0.25378114
A6: Grand Total | B6: 1
A12: Average of AuditScore | B12: Count of FineGBP | C12: Sum of FineGBP | E12: Average Audit Score | F12: =A13 -> 34.637233
A13: 34.637233 | B13: 4496 | C13: 49567413 | E13: Number of fines | F13: =B13 -> 4496
E14: Total fines cost | F14: =C13 -> 49567413
A20: Row Labels | B20: Count of Compliance | E20: Compliance | F20: Compliance %
A21: Compliant | B21: 0.4944395 | E21: =A21 -> Compliant | F21: =B21 -> 0.4944395 | H21: Target Value | I21: =B21 -> 0.4944395
A22: Non-Compliant | B22: 0.25177936 | E22: =A22 -> Non-Compliant | F22: =B22 -> 0.25177936 | H22: Needle Width | I22: 0.02
A23: Pending | B23: 0.25378114 | E23: =A23 -> Pending | F23: =B23 -> 0.25378114 | H23: Remaining Space | I23: =200%-I21-I22 -> 1.4855605
A24: Grand Total | B24: 1 | E24: Hidden Base | F24: =SUM(F21:F23) -> 1
A36: Plant | B36: Sum of AuditScore
A37: Torness | B37: 23436
A38: Bruce A | B38: 25203
A39: Olkiluoto 3 | B39: 25387
A40: Sizewell B | B40: 26451
A41: Diablo Canyon | B41: 26621
A42: Heysham 1 | B42: 28631
A52: Row Labels | B52: Count of Compliance
A53: Compliant | B53: 1
A54: Cancelled | B54: 0.25865947
A55: Closed | B55: 0.25326136
A56: In Progress | B56: 0.24876293
A57: Open | B57: 0.23931624
A71: Row Labels | B71: Sum of AuditScore | D71: Date | E71: Audio Score
A72: 2022 | D72: =A72 -> 2022 | E72: =B72 -> 0
A73: Jan | B73: 3797 | D73: =A73 -> Jan | E73: =B73 -> 3797
A74: Feb | B74: 2102 | D74: =A74 -> Feb | E74: =B74 -> 2102
A75: Mar | B75: 3680 | D75: =A75 -> Mar | E75: =B75 -> 3680
A76: Apr | B76: 3494 | D76: =A76 -> Apr | E76: =B76 -> 3494
A77: May | B77: 4189 | D77: =A77 -> May | E77: =B77 -> 4189
A78: Jun | B78: 3268 | D78: =A78 -> Jun | E78: =B78 -> 3268
A79: Jul | B79: 3001 | D79: =A79 -> Jul | E79: =B79 -> 3001
A80: Aug | B80: 3803 | D80: =A80 -> Aug | E80: =B80 -> 3803
A81: Sep | B81: 2935 | D81: =A81 -> Sep | E81: =B81 -> 2935
A82: Oct | B82: 3147 | D82: =A82 -> Oct | E82: =B82 -> 3147
A83: Nov | B83: 3666 | D83: =A83 -> Nov | E83: =B83 -> 3666
A84: Dec | B84: 2938 | D84: =A84 -> Dec | E84: =B84 -> 2938
...

Sheet Regulatory Compliance Dashboard
M2: Regulatory Compliance Dashboard

Sheet Inventory Optimisation Pivot
A3: Average Inventory | B3: Negative Stock | C3: Low Stock | D3: Reorder Needed | E3: Current Stock | G3: Average Inventory | H3: Negative Stock | I3: Low Stock | J3: Reorder Needed | K3: Current Stock
A4: 244.4851 | B4: 43 | C4: 347 | D4: 360 | E4: 1099205 | G4: =A4 -> 244.4851 | H4: =B4 -> 43 | I4: =C4 -> 347 | J4: =D4 -> 360 | K4: =E4 -> 1099205
A10: Part | B10: Current Stock
A11: P1327 | B11: 4269
A12: P1201 | B12: 4720
A13: P1027 | B13: 4812
A14: P1399 | B14: 4898
A15: P1463 | B15: 4916
A16: P1099 | B16: 4929
A17: P1153 | B17: 5860
A18: P1452 | B18: 6093
A19: P1386 | B19: 6234
A20: P1372 | B20: 6298
A21: Grand Total | B21: 53029
A516: Inventory Level | C516: Inventory Level
A517: -5 | C517: =A517 -> -5
A518: -4 | C518: =A518 -> -4
A519: -3 | C519: =A519 -> -3
A520: -2 | C520: =A520 -> -2
A521: -1 | C521: =A521 -> -1
A522: 0 | C522: =A522 -> 0
A523: 1 | C523: =A523 -> 1
A524: 2 | C524: =A524 -> 2
A525: 3 | C525: =A525 -> 3
A526: 4 | C526: =A526 -> 4
A527: 5 | C527: =A527 -> 5
A528: 6 | C528: =A528 -> 6
... A1022: 500 | C1022: =A1022 -> 500
A1023: Grand Total
A1027: Row Labels | B1027: Current Stock | D1027: Reorder | E1027: Current Stock | F1027: Inventory Status
A1028: 18 | B1028: 13072 | D1028: =A1028 -> 18 | E1028: =B1028 -> 13072 | F1028: =IF(E1028<0,"Negative Stock",IF(E1028<=D1028,"Reorder Point","Healthy")) -> Healthy
A1029: 19 | B1029: 11588 | D1029: =A1029 -> 19 | E1029: =B1029 -> 11588 | F1029: =IF(E1029<0,"Negative Stock",IF(E1029<=D1029,"Reorder Point","Healthy")) -> Healthy | J1029: Negative Stock
A1030: 22 | B1030: 13719 | D1030: =A1030 -> 22 | E1030: =B1030 -> 13719 | F1030: =IF(E1030<0,"Negative Stock",IF(E1030<=D1030,"Reorder Point","Healthy")) -> Healthy | J1030: Reorder Point
A1031: 27 | B1031: 11903 | D1031: =A1031 -> 27 | E1031: =B1031 -> 11903 | F1031: =IF(E1031<0,"Negative Stock",IF(E1031<=D1031,"Reorder Point","Healthy")) -> Healthy | J1031: Healthy
A1032: 30 | B1032: 12608 | D1032: =A1032 -> 30 | E1032: =B1032 -> 12608 | F1032: =IF(E1032<0,"Negative Stock",IF(E1032<=D1032,"Reorder Point","Healthy")) -> Healthy
A1033: 36 | B1033: 12461 | D1033: =A1033 -> 36 | E1033: =B1033 -> 12461 | F1033: =IF(E1033<0,"Negative Stock",IF(E1033<=D1033,"Reorder Point","Healthy")) -> Healthy
A1034: 46 | B1034: 12334 | D1034: =A1034 -> 46 | E1034: =B1034 -> 12334 | F1034: =IF(E1034<0,"Negative Stock",IF(E1034<=D1034,"Reorder Point","Healthy")) -> Healthy
A1035: 49 | B1035: 13752 | D1035: =A1035 -> 49 | E1035: =B1035 -> 13752 | F1035: =IF(E1035<0,"Negative Stock",IF(E1035<=D1035,"Reorder Point","Healthy")) -> Healthy
A1036: 53 | B1036: 12362 | D1036: =A1036 -> 53 | E1036: =B1036 -> 12362 | F1036: =IF(E1036<0,"Negative Stock",IF(E1036<=D1036,"Reorder Point","Healthy")) -> Healthy
A1037: 64 | B1037: 11588 | D1037: =A1037 -> 64 | E1037: =B1037 -> 11588 | F1037: =IF(E1037<0,"Negative Stock",IF(E1037<=D1037,"Reorder Point","Healthy")) -> Healthy
...

Sheet Inventory Dashboard
E2: Inventory Optimisation Dashboard
B16: Top 20 Inventory Status
B17: Reorder | C17: Current Stock | D17: Inventory Status | F17: Legend
B18: ='Inventory Optimisation Pivot'!D1028 -> 18 | C18: ='Inventory Optimisation Pivot'!E1028 -> 13072 | D18: =IF(C18<0,"Critical",IF(C18<=B18,"Below Reorder","Healthy")) -> Healthy | G18: Negative Stock
B19: ='Inventory Optimisation Pivot'!D1029 -> 19 | C19: ='Inventory Optimisation Pivot'!E1029 -> 11588 | D19: =IF(C19<0,"Critical",IF(C19<=B19,"Below Reorder","Healthy")) -> Healthy | G19: Reorder Point
B20: ='Inventory Optimisation Pivot'!D1030 -> 22 | C20: ='Inventory Optimisation Pivot'!E1030 -> 13719 | D20: =IF(C20<0,"Critical",IF(C20<=B20,"Below Reorder","Healthy")) -> Healthy | G20: Healthy
B21: ='Inventory Optimisation Pivot'!D1031 -> 27 | C21: ='Inventory Optimisation Pivot'!E1031 -> 11903 | D21: =IF(C21<0,"Critical",IF(C21<=B21,"Below Reorder","Healthy")) -> Healthy
B22: ='Inventory Optimisation Pivot'!D1032 -> 30 | C22: ='Inventory Optimisation Pivot'!E1032 -> 12608 | D22: =IF(C22<0,"Critical",IF(C22<=B22,"Below Reorder","Healthy")) -> Healthy
B23: ='Inventory Optimisation Pivot'!D1033 -> 36 | C23: ='Inventory Optimisation Pivot'!E1033 -> 12461 | D23: =IF(C23<0,"Critical",IF(C23<=B23,"Below Reorder","Healthy")) -> Healthy
B24: ='Inventory Optimisation Pivot'!D1034 -> 46 | C24: ='Inventory Optimisation Pivot'!E1034 -> 12334 | D24: =IF(C24<0,"Critical",IF(C24<=B24,"Below Reorder","Healthy")) -> Healthy
B25: ='Inventory Optimisation Pivot'!D1035 -> 49 | C25: ='Inventory Optimisation Pivot'!E1035 -> 13752 | D25: =IF(C25<0,"Critical",IF(C25<=B25,"Below Reorder","Healthy")) -> Healthy
B26: ='Inventory Optimisation Pivot'!D1036 -> 53 | C26: ='Inventory Optimisation Pivot'!E1036 -> 12362 | D26: =IF(C26<0,"Critical",IF(C26<=B26,"Below Reorder","Healthy")) -> Healthy
B27: ='Inventory Optimisation Pivot'!D1037 -> 64 | C27: ='Inventory Optimisation Pivot'!E1037 -> 11588 | D27: =IF(C27<0,"Critical",IF(C27<=B27,"Below Reorder","Healthy")) -> Healthy
B28: ='Inventory Optimisation Pivot'!D1038 -> 72 | C28: ='Inventory Optimisation Pivot'!E1038 -> 12319 | D28: =IF(C28<0,"Critical",IF(C28<=B28,"Below Reorder","Healthy")) -> Healthy
B29: ='Inventory Optimisation Pivot'!D1039 -> 76 | C29: ='Inventory Optimisation Pivot'!E1039 -> 12513 | D29: =IF(C29<0,"Critical",IF(C29<=B29,"Below Reorder","Healthy")) -> Healthy
B30: ='Inventory Optimisation Pivot'!D1040 -> 81 | C30: ='Inventory Optimisation Pivot'!E1040 -> 12208 | D30: =IF(C30<0,"Critical",IF(C30<=B30,"Below Reorder","Healthy")) -> Healthy
B31: ='Inventory Optimisation Pivot'!D1041 -> 86 | C31: ='Inventory Optimisation Pivot'!E1041 -> 12479 | D31: =IF(C31<0,"Critical",IF(C31<=B31,"Below Reorder","Healthy")) -> Healthy
B32: ='Inventory Optimisation Pivot'!D1042 -> 93 | C32: ='Inventory Optimisation Pivot'!E1042 -> 12182 | D32: =IF(C32<0,"Critical",IF(C32<=B32,"Below Reorder","Healthy")) -> Healthy
... B37: ='Inventory Optimisation Pivot'!D1047 -> 107 | C37: ='Inventory Optimisation Pivot'!E1047 -> 11688 | D37: =IF(C37<0,"Critical",IF(C37<=B37,"Below Reorder","Healthy")) -> Healthy

Sheet Downtime Root Cause Pivot
A2: Root Cause | B2: Sum of DowntimeHours | D2: Root Cause | E2: Downtime
A3: Ageing | B3: 8926 | D3: =A3 -> Ageing | E3: =B3 -> 8926
A4: Design | B4: 9332 | D4: =A4 -> Design | E4: =B4 -> 9332
A5: Human Error | B5: 9120 | D5: =A5 -> Human Error | E5: =B5 -> 9120
A6: Unknown | B6: 9142 | D6: =A6 -> Unknown | E6: =B6 -> 9142
A7: Vendor Delay | B7: 9055 | D7: =A7 -> Vendor Delay | E7: =B7 -> 9055
A18: Row Labels | B18: Sum of LostMWh | D18: Plant | E18: LostMWh
A19: Bruce A | B19: 309304.9 | D19: =A19 -> Bruce A | E19: =B19 -> 309304.9
A20: Diablo Canyon | B20: 350866.6 | D20: =A20 -> Diablo Canyon | E20: =B20 -> 350866.6
A21: Heysham 1 | B21: 346621.1 | D21: =A21 -> Heysham 1 | E21: =B21 -> 346621.1
A22: Olkiluoto 3 | B22: 319434.5 | D22: =A22 -> Olkiluoto 3 | E22: =B22 -> 319434.5
A23: Sizewell B | B23: 322467.2 | D23: =A23 -> Sizewell B | E23: =B23 -> 322467.2
A24: Torness | B24: 312746 | D24: =A24 -> Torness | E24: =B24 -> 312746
A33: Root Cause | B33: Count of RootCause
A34: Ageing | B34: 886
A35: Design | B35: 896
A36: Human Error | B36: 913
A37: Unknown | B37: 894
A38: Vendor Delay | B38: 907
A39: Grand Total | B39: 4496

Sheet Downtime Root Cause Dashboard
E2: Downtime Root Cause Dashboard
